INFO:django.utils.autoreload:C:\Users\ManishKumar\Desktop\Vijay_assignment1\Active_Backlogs\backlogs1_app\views.py changed, reloading.
ERROR:django.request:Internal Server Error: /student_basic/api/
Traceback (most recent call last):
  File "C:\Users\ManishKumar\Desktop\Vijay_assignment1\venv\lib\site-packages\django\core\handlers\exception.py", line 47, in inner
    response = get_response(request)
  File "C:\Users\ManishKumar\Desktop\Vijay_assignment1\venv\lib\site-packages\django\core\handlers\base.py", line 179, in _get_response
    response = wrapped_callback(request, *callback_args, **callback_kwargs)
  File "C:\Users\ManishKumar\Desktop\Vijay_assignment1\venv\lib\site-packages\django\views\generic\base.py", line 70, in view
    return self.dispatch(request, *args, **kwargs)
  File "C:\Users\ManishKumar\Desktop\Vijay_assignment1\venv\lib\site-packages\django\utils\decorators.py", line 43, in _wrapper
    return bound_method(*args, **kwargs)
  File "C:\Users\ManishKumar\Desktop\Vijay_assignment1\venv\lib\site-packages\django\views\decorators\csrf.py", line 54, in wrapped_view
    return view_func(*args, **kwargs)
  File "C:\Users\ManishKumar\Desktop\Vijay_assignment1\venv\lib\site-packages\django\views\generic\base.py", line 98, in dispatch
    return handler(request, *args, **kwargs)
  File "C:\Users\ManishKumar\Desktop\Vijay_assignment1\Active_Backlogs\backlogs1_app\views.py", line 112, in delete
    status, deleted_item = stud_obj.delete()
  File "C:\Users\ManishKumar\Desktop\Vijay_assignment1\venv\lib\site-packages\django\db\models\base.py", line 946, in delete
    collector.collect([self], keep_parents=keep_parents)
  File "C:\Users\ManishKumar\Desktop\Vijay_assignment1\venv\lib\site-packages\django\db\models\deletion.py", line 308, in collect
    set(chain.from_iterable(protected_objects.values())),
django.db.models.deletion.ProtectedError: ("Cannot delete some instances of model 'Student' because they are referenced through protected foreign keys: 'Backlogs.B_id'.", {<Backlogs: Backlogs object (10090)>})
INFO:django.utils.autoreload:C:\Users\ManishKumar\Desktop\Vijay_assignment1\Active_Backlogs\backlogs1_app\models.py changed, reloading.
ERROR:django.request:Internal Server Error: /student_basic/api/
Traceback (most recent call last):
  File "C:\Users\ManishKumar\Desktop\Vijay_assignment1\venv\lib\site-packages\django\db\backends\utils.py", line 84, in _execute
    return self.cursor.execute(sql, params)
  File "C:\Users\ManishKumar\Desktop\Vijay_assignment1\venv\lib\site-packages\django\db\backends\sqlite3\base.py", line 413, in execute
    return Database.Cursor.execute(self, query, params)
sqlite3.IntegrityError: FOREIGN KEY constraint failed

The above exception was the direct cause of the following exception:

Traceback (most recent call last):
  File "C:\Users\ManishKumar\Desktop\Vijay_assignment1\venv\lib\site-packages\django\core\handlers\exception.py", line 47, in inner
    response = get_response(request)
  File "C:\Users\ManishKumar\Desktop\Vijay_assignment1\venv\lib\site-packages\django\core\handlers\base.py", line 179, in _get_response
    response = wrapped_callback(request, *callback_args, **callback_kwargs)
  File "C:\Users\ManishKumar\Desktop\Vijay_assignment1\venv\lib\site-packages\django\views\generic\base.py", line 70, in view
    return self.dispatch(request, *args, **kwargs)
  File "C:\Users\ManishKumar\Desktop\Vijay_assignment1\venv\lib\site-packages\django\utils\decorators.py", line 43, in _wrapper
    return bound_method(*args, **kwargs)
  File "C:\Users\ManishKumar\Desktop\Vijay_assignment1\venv\lib\site-packages\django\views\decorators\csrf.py", line 54, in wrapped_view
    return view_func(*args, **kwargs)
  File "C:\Users\ManishKumar\Desktop\Vijay_assignment1\venv\lib\site-packages\django\views\generic\base.py", line 98, in dispatch
    return handler(request, *args, **kwargs)
  File "C:\Users\ManishKumar\Desktop\Vijay_assignment1\Active_Backlogs\backlogs1_app\views.py", line 112, in delete
    status, deleted_item = stud_obj.delete()
  File "C:\Users\ManishKumar\Desktop\Vijay_assignment1\venv\lib\site-packages\django\db\models\base.py", line 947, in delete
    return collector.delete()
  File "C:\Users\ManishKumar\Desktop\Vijay_assignment1\venv\lib\site-packages\django\db\models\deletion.py", line 396, in delete
    count = sql.DeleteQuery(model).delete_batch([instance.pk], self.using)
  File "C:\Users\ManishKumar\Desktop\Vijay_assignment1\venv\lib\site-packages\django\db\models\sql\subqueries.py", line 43, in delete_batch
    num_deleted += self.do_query(self.get_meta().db_table, self.where, using=using)
  File "C:\Users\ManishKumar\Desktop\Vijay_assignment1\venv\lib\site-packages\django\db\models\sql\subqueries.py", line 23, in do_query
    cursor = self.get_compiler(using).execute_sql(CURSOR)
  File "C:\Users\ManishKumar\Desktop\Vijay_assignment1\venv\lib\site-packages\django\db\models\sql\compiler.py", line 1156, in execute_sql
    cursor.execute(sql, params)
  File "C:\Users\ManishKumar\Desktop\Vijay_assignment1\venv\lib\site-packages\django\db\backends\utils.py", line 98, in execute
    return super().execute(sql, params)
  File "C:\Users\ManishKumar\Desktop\Vijay_assignment1\venv\lib\site-packages\django\db\backends\utils.py", line 66, in execute
    return self._execute_with_wrappers(sql, params, many=False, executor=self._execute)
  File "C:\Users\ManishKumar\Desktop\Vijay_assignment1\venv\lib\site-packages\django\db\backends\utils.py", line 75, in _execute_with_wrappers
    return executor(sql, params, many, context)
  File "C:\Users\ManishKumar\Desktop\Vijay_assignment1\venv\lib\site-packages\django\db\backends\utils.py", line 84, in _execute
    return self.cursor.execute(sql, params)
  File "C:\Users\ManishKumar\Desktop\Vijay_assignment1\venv\lib\site-packages\django\db\utils.py", line 90, in __exit__
    raise dj_exc_value.with_traceback(traceback) from exc_value
  File "C:\Users\ManishKumar\Desktop\Vijay_assignment1\venv\lib\site-packages\django\db\backends\utils.py", line 84, in _execute
    return self.cursor.execute(sql, params)
  File "C:\Users\ManishKumar\Desktop\Vijay_assignment1\venv\lib\site-packages\django\db\backends\sqlite3\base.py", line 413, in execute
    return Database.Cursor.execute(self, query, params)
django.db.utils.IntegrityError: FOREIGN KEY constraint failed
INFO:django.utils.autoreload:C:\Users\ManishKumar\Desktop\Vijay_assignment1\Active_Backlogs\backlogs1_app\models.py changed, reloading.
ERROR:root:deleted successfully
INFO:django.utils.autoreload:C:\Users\ManishKumar\Desktop\Vijay_assignment1\Active_Backlogs\backlogs1_app\views.py changed, reloading.
